Traceback (most recent call last):
  File "/home/jaimie/miniconda3/envs/jupyterbook/lib/python3.10/site-packages/jupyter_cache/executors/utils.py", line 58, in single_nb_execution
    executenb(
  File "/home/jaimie/miniconda3/envs/jupyterbook/lib/python3.10/site-packages/nbclient/client.py", line 1314, in execute
    return NotebookClient(nb=nb, resources=resources, km=km, **kwargs).execute()
  File "/home/jaimie/.local/lib/python3.10/site-packages/jupyter_core/utils/__init__.py", line 165, in wrapped
    return loop.run_until_complete(inner)
  File "/home/jaimie/miniconda3/envs/jupyterbook/lib/python3.10/asyncio/base_events.py", line 649, in run_until_complete
    return future.result()
  File "/home/jaimie/miniconda3/envs/jupyterbook/lib/python3.10/site-packages/nbclient/client.py", line 709, in async_execute
    await self.async_execute_cell(
  File "/home/jaimie/miniconda3/envs/jupyterbook/lib/python3.10/site-packages/nbclient/client.py", line 1062, in async_execute_cell
    await self._check_raise_for_error(cell, cell_index, exec_reply)
  File "/home/jaimie/miniconda3/envs/jupyterbook/lib/python3.10/site-packages/nbclient/client.py", line 918, in _check_raise_for_error
    raise CellExecutionError.from_cell_and_msg(cell, exec_reply_content)
nbclient.exceptions.CellExecutionError: An error occurred while executing the following cell:
------------------
# Imports
import pandas as pd
import matplotlib.patches as mpatches
import matplotlib.pyplot as plt
import matplotlib.colors as mcolors
import numpy as np
import seaborn as sns
import geopandas as gpd

ems_2020_rel = pd.read_csv('../graphA/mergeN.csv', usecols=['Area','2020rel'])
ems_2020_relTREES = pd.read_csv('../graphA/mergeY.csv', usecols=['Area','2020rel'])


------------------


[0;31m---------------------------------------------------------------------------[0m
[0;31mModuleNotFoundError[0m                       Traceback (most recent call last)
Cell [0;32mIn[1], line 8[0m
[1;32m      6[0m [38;5;28;01mimport[39;00m [38;5;21;01mnumpy[39;00m [38;5;28;01mas[39;00m [38;5;21;01mnp[39;00m
[1;32m      7[0m [38;5;28;01mimport[39;00m [38;5;21;01mseaborn[39;00m [38;5;28;01mas[39;00m [38;5;21;01msns[39;00m
[0;32m----> 8[0m [38;5;28;01mimport[39;00m [38;5;21;01mgeopandas[39;00m [38;5;28;01mas[39;00m [38;5;21;01mgpd[39;00m
[1;32m     10[0m ems_2020_rel [38;5;241m=[39m pd[38;5;241m.[39mread_csv([38;5;124m'[39m[38;5;124m../graphA/mergeN.csv[39m[38;5;124m'[39m, usecols[38;5;241m=[39m[[38;5;124m'[39m[38;5;124mArea[39m[38;5;124m'[39m,[38;5;124m'[39m[38;5;124m2020rel[39m[38;5;124m'[39m])
[1;32m     11[0m ems_2020_relTREES [38;5;241m=[39m pd[38;5;241m.[39mread_csv([38;5;124m'[39m[38;5;124m../graphA/mergeY.csv[39m[38;5;124m'[39m, usecols[38;5;241m=[39m[[38;5;124m'[39m[38;5;124mArea[39m[38;5;124m'[39m,[38;5;124m'[39m[38;5;124m2020rel[39m[38;5;124m'[39m])

[0;31mModuleNotFoundError[0m: No module named 'geopandas'

